Workbook

Sheet Calc-dash_ops
A3: Étiquettes de lignes | B3: Somme de revenue
A4: janv | B4: 1613.79
A5: févr | B5: 22662.15
A6: mars | B6: 59919.91
A7: avr | B7: 81789.4
A8: mai | B8: 100749.2
A9: juin | B9: 32176.69
A10: Total général | B10: 298911.14

Sheet DATA_kpi_daily
A1: purchase_day | B1: tickets_sold | C1: revenue | D1: avg_basket | E1: avg_lead_time | F1: tx_count
A2: 46029 | B2: 1 | C2: 15.81 | D2: 15.81 | E2: 62 | F2: 1
A3: 46031 | B3: 1 | C3: 11.89 | D3: 11.89 | E3: 57 | F3: 1
A4: 46036 | B4: 3 | C4: 11.96 | D4: 5.98 | E4: 54.5 | F4: 2
A5: 46037 | B5: 5 | C5: 63.31 | D5: 21.103333 | E5: 55.333333 | F5: 3
A6: 46040 | B6: 1 | C6: 12.01 | D6: 12.01 | E6: 58 | F6: 1
A7: 46041 | B7: 1 | C7: 15.78 | D7: 15.78 | E7: 50 | F7: 1
A8: 46042 | B8: 6 | C8: 73.41 | D8: 24.47 | E8: 49.333333 | F8: 3
A9: 46043 | B9: 1 | C9: 0 | D9: 0 | E9: 50 | F9: 1
A10: 46044 | B10: 12 | C10: 203.28 | D10: 29.04 | E10: 47 | F10: 7
A11: 46046 | B11: 6 | C11: 158.35 | D11: 39.5875 | E11: 49.75 | F11: 4
A12: 46047 | B12: 9 | C12: 135.15 | D12: 19.307143 | E12: 44.428571 | F12: 7
A13: 46048 | B13: 3 | C13: 67.62 | D13: 33.81 | E13: 44 | F13: 2
... A165: 46200 | B165: 127 | C165: 1223.35 | D165: 18.820769 | E165: 0.21538462 | F165: 65

Sheet KPI_event
A3: Étiquettes de lignes | B3: Somme de revenue
A4: Danse — Session 18 | B4: 60938.65
A5: Théâtre — Session 2 | B5: 27654.45
A6: Projection — Session 5 | B6: 23478.3
A7: Conférence — Session 1 | B7: 21645.67
A8: Stand-up — Session 7 | B8: 18073.07
A9: Conférence — Session 20 | B9: 14553.74
A10: Danse — Session 13 | B10: 13238.34
A11: Danse — Session 11 | B11: 10505.24
A12: Danse — Session 24 | B12: 10016.74
A13: Projection — Session 16 | B13: 8999.5
A14: Total général | B14: 209103.7

Sheet DATA_kpi_event
A1: event_id | B1: tickets_sold | C1: revenue | D1: avg_basket | E1: first_purchase | F1: last_purchase | G1: no_show_rate | H1: event_name | I1: venue_name | J1: event_datetime | K1: capacity | L1: fill_rate | M1: genre
A2: E001 | B2: 568 | C2: 21645.67 | D2: 66.397761 | E2: 45711.174 | F2: 45770.75 | G2: 0.076687117 | H2: Conférence — Session 1 | I2: Théâtre du Panier | J2: 46135.792 | K2: 400 | L2: 0.785 | M2: =IFERROR(INDEX(DATA_dim_events!$G:$G,MATCH($A2,DATA_dim_events!$A:$A,0)),"") -> Conférence
A3: E002 | B3: 1459 | C3: 27654.45 | D3: 33.479964 | E3: 45754.326 | F3: 45822.708 | G3: 0.088377724 | H3: Théâtre — Session 2 | I3: La Friche (scène) | J3: 46187.75 | K3: 1200 | L3: 0.69833333 | M3: =IFERROR(INDEX(DATA_dim_events!$G:$G,MATCH($A3,DATA_dim_events!$A:$A,0)),"") -> Théâtre
A4: E003 | B4: 347 | C4: 4533.52 | D4: 22.443168 | E4: 45666.479 | F4: 45722.708 | G4: 0.094059406 | H4: Projection — Session 3 | I4: Théâtre Canebière | J4: 46087.75 | K4: 250 | L4: 0.492 | M4: =IFERROR(INDEX(DATA_dim_events!$G:$G,MATCH($A4,DATA_dim_events!$A:$A,0)),"") -> Projection
A5: E004 | B5: 182 | C5: 5596.17 | D5: 51.816389 | E5: 45776.521 | F5: 45833.708 | G5: 0.064814815 | H5: Théâtre — Session 4 | I5: Le Dôme (club) | J5: 46198.75 | K5: 150 | L5: 0.55333333 | M5: =IFERROR(INDEX(DATA_dim_events!$G:$G,MATCH($A5,DATA_dim_events!$A:$A,0)),"") -> Théâtre
A6: E005 | B6: 994 | C6: 23478.3 | D6: 41.19 | E6: 45736.306 | F6: 45798.75 | G6: 0.070175439 | H6: Projection — Session 5 | I6: Le Dôme (club) | J6: 46163.792 | K6: 700 | L6: 0.51142857 | M6: =IFERROR(INDEX(DATA_dim_events!$G:$G,MATCH($A6,DATA_dim_events!$A:$A,0)),"") -> Projection
A7: E006 | B7: 146 | C7: 5787.47 | D7: 68.087882 | E7: 45681.528 | F7: 45748.833 | G7: 0.12941176 | H7: Festival — Session 6 | I7: Dock des Suds (fiction) | J7: 46113.875 | K7: 150 | L7: 0.76666667 | M7: =IFERROR(INDEX(DATA_dim_events!$G:$G,MATCH($A7,DATA_dim_events!$A:$A,0)),"") -> Festival
A8: E007 | B8: 1396 | C8: 18073.07 | D8: 22.506936 | E8: 45698.542 | F8: 45758.792 | G8: 0.097135741 | H8: Stand-up — Session 7 | I8: Dock des Suds (fiction) | J8: 46123.833 | K8: 1200 | L8: 0.7825 | M8: =IFERROR(INDEX(DATA_dim_events!$G:$G,MATCH($A8,DATA_dim_events!$A:$A,0)),"") -> Stand-up
A9: E008 | B9: 323 | C9: 4194.96 | D9: 21.963141 | E9: 45685.292 | F9: 45735.792 | G9: 0.089005236 | H9: Concert — Session 8 | I9: Théâtre du Panier | J9: 46100.833 | K9: 250 | L9: 0.9 | M9: =IFERROR(INDEX(DATA_dim_events!$G:$G,MATCH($A9,DATA_dim_events!$A:$A,0)),"") -> Concert
A10: E009 | B10: 450 | C10: 8741.7 | D10: 34.689286 | E10: 45664.694 | F10: 45725.833 | G10: 0.091269841 | H10: Danse — Session 9 | I10: Espace Joliette | J10: 46090.875 | K10: 400 | L10: 0.5875 | M10: =IFERROR(INDEX(DATA_dim_events!$G:$G,MATCH($A10,DATA_dim_events!$A:$A,0)),"") -> Danse
A11: E010 | B11: 469 | C11: 7366.46 | D11: 26.690072 | E11: 45672.59 | F11: 45732.792 | G11: 0.076086957 | H11: Projection — Session 10 | I11: Théâtre du Panier | J11: 46097.833 | K11: 400 | L11: 0.6525 | M11: =IFERROR(INDEX(DATA_dim_events!$G:$G,MATCH($A11,DATA_dim_events!$A:$A,0)),"") -> Projection
A12: E011 | B12: 803 | C12: 10505.24 | D12: 22.20981 | E12: 45702.562 | F12: 45754.708 | G12: 0.069767442 | H12: Danse — Session 11 | I12: Espace Joliette | J12: 46119.75 | K12: 700 | L12: 0.82857143 | M12: =IFERROR(INDEX(DATA_dim_events!$G:$G,MATCH($A12,DATA_dim_events!$A:$A,0)),"") -> Danse
A13: E012 | B13: 533 | C13: 8378.89 | D13: 26.855417 | E13: 45679.604 | F13: 45732.75 | G13: 0.092948718 | H13: Concert — Session 12 | I13: Le Dôme (club) | J13: 46097.792 | K13: 400 | L13: 0.9325 | M13: =IFERROR(INDEX(DATA_dim_events!$G:$G,MATCH($A13,DATA_dim_events!$A:$A,0)),"") -> Concert
... A25: E024 | B25: 531 | C25: 10016.74 | D25: 31.900446 | E25: 45689.257 | F25: 45746.75 | G25: 0.10191083 | H25: Danse — Session 24 | I25: Salle du Vieux-Port | J25: 46111.792 | K25: 400 | L25: 0.58 | M25: =IFERROR(INDEX(DATA_dim_events!$G:$G,MATCH($A25,DATA_dim_events!$A:$A,0)),"") -> Danse

Sheet DATA_dim_events
A1: event_id | B1: event_name | C1: venue_name | D1: event_datetime | E1: capacity | F1: base_price | G1: genre | H1: quartier_zone
A2: E003 | B2: Projection — Session 3 | C2: Théâtre Canebière | D2: 46087.75 | E2: 250 | F2: 15 | G2: Projection | H2: Le Panier
A3: E009 | B3: Danse — Session 9 | C3: Espace Joliette | D3: 46090.875 | E3: 400 | F3: 22 | G3: Danse | H3: Les Goudes
A4: E017 | B4: Stand-up — Session 17 | C4: Le Dôme (club) | D4: 46092.792 | E4: 150 | F4: 45 | G4: Stand-up | H4: Belle de Mai
A5: E012 | B5: Concert — Session 12 | C5: Le Dôme (club) | D5: 46097.792 | E5: 400 | F5: 18 | G5: Concert | H5: L’Estaque
A6: E010 | B6: Projection — Session 10 | C6: Théâtre du Panier | D6: 46097.833 | E6: 400 | F6: 18 | G6: Projection | H6: La Joliette
A7: E008 | B7: Concert — Session 8 | C7: Théâtre du Panier | D7: 46100.833 | E7: 250 | F7: 15 | G7: Concert | H7: La Joliette
A8: E024 | B8: Danse — Session 24 | C8: Salle du Vieux-Port | D8: 46111.792 | E8: 400 | F8: 22 | G8: Danse | H8: La Plaine
A9: E006 | B9: Festival — Session 6 | C9: Dock des Suds (fiction) | D9: 46113.875 | E9: 150 | F9: 45 | G9: Festival | H9: Vieux-Port
A10: E011 | B10: Danse — Session 11 | C10: Espace Joliette | D10: 46119.75 | E10: 700 | F10: 15 | G10: Danse | H10: Saint-Barnabé
A11: E007 | B11: Stand-up — Session 7 | C11: Dock des Suds (fiction) | D11: 46123.833 | E11: 1200 | F11: 15 | G11: Stand-up | H11: Cours Julien
A12: E001 | B12: Conférence — Session 1 | C12: Théâtre du Panier | D12: 46135.792 | E12: 400 | F12: 45 | G12: Conférence | H12: Vieux-Port
A13: E013 | B13: Danse — Session 13 | C13: Théâtre du Panier | D13: 46135.875 | E13: 400 | F13: 28 | G13: Danse | H13: La Joliette
... A25: E015 | B25: Théâtre — Session 15 | C25: Dock des Suds (fiction) | D25: 46200.792 | E25: 700 | F25: 12 | G25: Théâtre | H25: Noailles

Sheet DATA_event_geo
A1: event_id | B1: quartier_zone | C1: revenue
A2: E003 | B2: Le Panier | C2: =IFERROR(INDEX(DATA_kpi_event[revenue],MATCH(A2,DATA_kpi_event[event_id],0)),"") -> 4533.52
A3: E009 | B3: Les Goudes | C3: =IFERROR(INDEX(DATA_kpi_event[revenue],MATCH(A3,DATA_kpi_event[event_id],0)),"") -> 8741.7
A4: E017 | B4: Belle de Mai | C4: =IFERROR(INDEX(DATA_kpi_event[revenue],MATCH(A4,DATA_kpi_event[event_id],0)),"") -> 8910.31
A5: E012 | B5: L’Estaque | C5: =IFERROR(INDEX(DATA_kpi_event[revenue],MATCH(A5,DATA_kpi_event[event_id],0)),"") -> 8378.89
A6: E010 | B6: La Joliette | C6: =IFERROR(INDEX(DATA_kpi_event[revenue],MATCH(A6,DATA_kpi_event[event_id],0)),"") -> 7366.46
A7: E008 | B7: La Joliette | C7: =IFERROR(INDEX(DATA_kpi_event[revenue],MATCH(A7,DATA_kpi_event[event_id],0)),"") -> 4194.96
A8: E024 | B8: La Plaine | C8: =IFERROR(INDEX(DATA_kpi_event[revenue],MATCH(A8,DATA_kpi_event[event_id],0)),"") -> 10016.74
A9: E006 | B9: Vieux-Port | C9: =IFERROR(INDEX(DATA_kpi_event[revenue],MATCH(A9,DATA_kpi_event[event_id],0)),"") -> 5787.47
A10: E011 | B10: Saint-Barnabé | C10: =IFERROR(INDEX(DATA_kpi_event[revenue],MATCH(A10,DATA_kpi_event[event_id],0)),"") -> 10505.24
A11: E007 | B11: Cours Julien | C11: =IFERROR(INDEX(DATA_kpi_event[revenue],MATCH(A11,DATA_kpi_event[event_id],0)),"") -> 18073.07
A12: E001 | B12: Vieux-Port | C12: =IFERROR(INDEX(DATA_kpi_event[revenue],MATCH(A12,DATA_kpi_event[event_id],0)),"") -> 21645.67
A13: E013 | B13: La Joliette | C13: =IFERROR(INDEX(DATA_kpi_event[revenue],MATCH(A13,DATA_kpi_event[event_id],0)),"") -> 13238.34
... A25: E015 | B25: Noailles | C25: =IFERROR(INDEX(DATA_kpi_event[revenue],MATCH(A25,DATA_kpi_event[event_id],0)),"") -> 8429.15

Sheet DASH_direction
A1: KPIs | B1: Valeur
A2: CA total | B2: =SUM(DATA_kpi_daily[revenue]) -> 298911.14
A3: Tickets vendus | B3: =SUM(DATA_kpi_daily[tickets_sold]) -> 15496
A4: Panier moyen | B4: =SUM(DATA_kpi_daily[revenue]) / SUM(DATA_kpi_daily[tx_count]) -> 33.323427
A5: Taux de remplissage moyen | B5: =SUMPRODUCT(DATA_kpi_event[fill_rate],DATA_kpi_event[capacity]) / SUM(DATA_kpi_event[capacity]) -> 0.6850996
E6: Le CA progresse fortement jusqu’à mai puis chute en juin ; la performance est concentrée sur quelques événements (Top 10 = ~70% du CA) et dominée par la Danse.
E23: Étiquettes de lignes | F23: Somme de revenue
A24: Étiquettes de lignes | B24: Somme de revenue | E24: Danse — Session 18 | F24: 60938.65 | I24: Étiquettes de lignes | J24: Somme de revenue
A25: janv | B25: 1613.79 | E25: Théâtre — Session 2 | F25: 27654.45 | I25: Danse | J25: 103440.67
A26: févr | B26: 22662.15 | E26: Projection — Session 5 | F26: 23478.3 | I26: Conférence | J26: 48073.81
A27: mars | B27: 59919.91 | E27: Conférence — Session 1 | F27: 21645.67 | I27: Théâtre | J27: 46817.88
A28: avr | B28: 81789.4 | E28: Stand-up — Session 7 | F28: 18073.07 | I28: Projection | J28: 44377.78
A29: mai | B29: 100749.2 | E29: Conférence — Session 20 | F29: 14553.74 | I29: Stand-up | J29: 33058.6
A30: juin | B30: 32176.69 | E30: Danse — Session 13 | F30: 13238.34 | I30: Concert | J30: 17354.93
A31: Total général | B31: 298911.14 | E31: Danse — Session 11 | F31: 10505.24 | I31: Festival | J31: 5787.47
E32: Danse — Session 24 | F32: 10016.74 | I32: Total général | J32: 298911.14
E33: Projection — Session 16 | F33: 8999.5
E34: Total général | F34: 209103.7
A36: BONUS
A38: Étiquettes de lignes | B38: Somme de revenue
A39: Belle de Mai | B39: 69848.96
A40: La Joliette | B40: 39353.5
A41: La Plaine | B41: 37671.19
A42: Vieux-Port | B42: 27433.14
A43: Saint-Loup | B43: 23478.3
A44: Saint-Barnabé | B44: 21332.13
A45: Cours Julien | B45: 18073.07
A46: Castellane | B46: 14828.09
A47: Pointe Rouge | B47: 10734.28
A48: Les Goudes | B48: 8741.7
A49: Noailles | B49: 8429.15
A50: L’Estaque | B50: 8378.89
... A53: Total général | B53: 298911.14

Sheet DASH_direction_tableaux
A2: KPIs | B2: CA total | C2: Tickets vendus | D2: Panier moyen | E2: Taux de remplissage moyen
A3: Valeurs | B3: =SUM(DATA_kpi_daily[revenue]) -> 298911.14 | C3: =SUM(DATA_kpi_daily[tickets_sold]) -> 15496 | D3: =SUM(DATA_kpi_daily[revenue]) / SUM(DATA_kpi_daily[tx_count]) -> 33.323427 | E3: =SUMPRODUCT(DATA_kpi_event[fill_rate],DATA_kpi_event[capacity]) / SUM(DATA_kpi_event[capacity]) -> 0.6850996 | G3: CA en hausse jusqu’à mai puis rupture en juin ; 10 événements concentrent ~70% du CA, avec une dominance du genre Danse.

Sheet DASH_ops
A1: Pilotage billeterie - Dashboard Ops | C1: Période analysée : | D1: ="du "&TEXT($B$4-6,"jj/mm/aaaa")&" au "&TEXT($B$4,"jj/mm/aaaa") -> du 21/06/2026 au 27/06/2026 | F1: Seuil alerte (%) : | G1: -0.1
A3: ALERTES
A4: Dernier jour data | B4: =MAX(DATA_kpi_daily[purchase_day]) -> 46200
A5: CA 7 derniers jours | B5: =SUMIFS(DATA_kpi_daily[revenue],DATA_kpi_daily[purchase_day],">="&$B$4-6,DATA_kpi_daily[purchase_day],"<="&$B$4) -> 4042.46 | D5: Panier moyen 7 jours | E5: =IFERROR(B5/B8,0) -> 24.062262
A6: CA 7 jours précédents | B6: =SUMIFS(DATA_kpi_daily[revenue],DATA_kpi_daily[purchase_day],">="&$B$4-13,DATA_kpi_daily[purchase_day],"<="&$B$4-7) -> 8486.6 | D6: Panier moyen 7 jours précédents | E6: =IFERROR(B6/B9,0) -> 30.527338
A7: Variation (%) | B7: =IFERROR((B5-B6)/B6,0) -> -0.52366554 | C7: =IF(B7<=$G$1,"⚠️ baisse","OK") -> ⚠️ baisse | D7: Var panier % | E7: =IFERROR((E5-E6)/E6,0) -> -0.21177989 | F7: =IF(E7<=$G$1,"⚠️ baisse","OK") -> ⚠️ baisse
A8: Nb de transactions | B8: =SUMIFS(DATA_kpi_daily[tx_count],DATA_kpi_daily[purchase_day],">="&$B$4-6,DATA_kpi_daily[purchase_day],"<="&$B$4) -> 168 | D8: Tickets 7 jours | E8: =SUMIFS(DATA_kpi_daily[tickets_sold],DATA_kpi_daily[purchase_day],">="&$B$4-6,DATA_kpi_daily[purchase_day],"<="&$B$4) -> 310
A9: Tx 7 jours précédents | B9: =SUMIFS(DATA_kpi_daily[tx_count],DATA_kpi_daily[purchase_day],">="&$B$4-13,DATA_kpi_daily[purchase_day],"<="&$B$4-7) -> 278 | D9: Tickets 7 jours précédents | E9: =SUMIFS(DATA_kpi_daily[tickets_sold],DATA_kpi_daily[purchase_day],">="&$B$4-13,DATA_kpi_daily[purchase_day],"<="&$B$4-7) -> 502 | K9: BASE
A10: Var Tx % | B10: =IFERROR((B8-B9)/B9,0) -> -0.39568345 | C10: =IF(B10<=$G$1,"⚠️ baisse","OK") -> ⚠️ baisse | D10: Var tickets % | E10: =IFERROR((E8-E9)/E9,0) -> -0.38247012 | F10: =IF(E10<=$G$1,"⚠️ baisse","OK") -> ⚠️ baisse
A12: DIAGNOSTICS
K13: tickets_sold | L13: revenue | M13: no_show_rate | N13: event_name | O13: fill_rate | P13: Capacité estimée | Q13: Manque à gagner estimé | R13: Impact no-show (€)
A14: Top 10 evènements "à risque" | K14: 2509 | L14: 60938.65 | M14: 0.081435473 | N14: Danse — Session 18 | O14: 0.6795 | P14: =IFERROR(ROUND(K14/O14,0),"") -> 3692 | Q14: =IFERROR(ROUND((1-O14)*L14/O14,0),"") -> 28743 | R14: =ROUND(L14*M14,0) -> 4963
B15: event_name | C15: tickets_sold | D15: revenue | E15: no_show_rate | F15: fill_rate | G15: Capacité estimée | H15: Manque à gagner estimé | K15: 1459 | L15: 27654.45 | M15: 0.088377724 | N15: Théâtre — Session 2 | O15: 0.69833333 | P15: =IFERROR(ROUND(K15/O15,0),"") -> 2089 | Q15: =IFERROR(ROUND((1-O15)*L15/O15,0),"") -> 11946 | R15: =ROUND(L15*M15,0) -> 2444
B16: Projection — Session 16 | C16: 703 | D16: 8999.5 | E16: 0.076190476 | F16: 0.42 | G16: 1674 | H16: 12428 | K16: 1396 | L16: 18073.07 | M16: 0.097135741 | N16: Stand-up — Session 7 | O16: 0.7825 | P16: =IFERROR(ROUND(K16/O16,0),"") -> 1784 | Q16: =IFERROR(ROUND((1-O16)*L16/O16,0),"") -> 5024 | R16: =ROUND(L16*M16,0) -> 1756
B17: Conférence — Session 20 | C17: 937 | D17: 14553.74 | E17: 0.089908257 | F17: 0.43285714 | G17: 2165 | H17: 19069 | K17: 568 | L17: 21645.67 | M17: 0.076687117 | N17: Conférence — Session 1 | O17: 0.785 | P17: =IFERROR(ROUND(K17/O17,0),"") -> 724 | Q17: =IFERROR(ROUND((1-O17)*L17/O17,0),"") -> 5928 | R17: =ROUND(L17*M17,0) -> 1660
B18: Projection — Session 3 | C18: 347 | D18: 4533.52 | E18: 0.094059406 | F18: 0.492 | G18: 705 | H18: 4681 | K18: 994 | L18: 23478.3 | M18: 0.070175439 | N18: Projection — Session 5 | O18: 0.51142857 | P18: =IFERROR(ROUND(K18/O18,0),"") -> 1944 | Q18: =IFERROR(ROUND((1-O18)*L18/O18,0),"") -> 22429 | R18: =ROUND(L18*M18,0) -> 1648
B19: Projection — Session 5 | C19: 994 | D19: 23478.3 | E19: 0.070175439 | F19: 0.51142857 | G19: 1944 | H19: 22429 | K19: 937 | L19: 14553.74 | M19: 0.089908257 | N19: Conférence — Session 20 | O19: 0.43285714 | P19: =IFERROR(ROUND(K19/O19,0),"") -> 2165 | Q19: =IFERROR(ROUND((1-O19)*L19/O19,0),"") -> 19069 | R19: =ROUND(L19*M19,0) -> 1309
B20: Théâtre — Session 4 | C20: 182 | D20: 5596.17 | E20: 0.064814815 | F20: 0.55333333 | G20: 329 | H20: 4517 | K20: 535 | L20: 13238.34 | M20: 0.078947368 | N20: Danse — Session 13 | O20: 0.65 | P20: =IFERROR(ROUND(K20/O20,0),"") -> 823 | Q20: =IFERROR(ROUND((1-O20)*L20/O20,0),"") -> 7128 | R20: =ROUND(L20*M20,0) -> 1045
B21: Danse — Session 24 | C21: 531 | D21: 10016.74 | E21: 0.10191083 | F21: 0.58 | G21: 916 | H21: 7254 | K21: 531 | L21: 10016.74 | M21: 0.10191083 | N21: Danse — Session 24 | O21: 0.58 | P21: =IFERROR(ROUND(K21/O21,0),"") -> 916 | Q21: =IFERROR(ROUND((1-O21)*L21/O21,0),"") -> 7254 | R21: =ROUND(L21*M21,0) -> 1021
B22: Danse — Session 9 | C22: 450 | D22: 8741.7 | E22: 0.091269841 | F22: 0.5875 | G22: 766 | H22: 6138 | K22: 838 | L22: 8429.15 | M22: 0.098532495 | N22: Théâtre — Session 15 | O22: 0.87571429 | P22: =IFERROR(ROUND(K22/O22,0),"") -> 957 | Q22: =IFERROR(ROUND((1-O22)*L22/O22,0),"") -> 1196 | R22: =ROUND(L22*M22,0) -> 831
B23: Conférence — Session 22 | C23: 191 | D23: 6045.81 | E23: 0.125 | F23: 0.62666667 | G23: 305 | H23: 3602 | K23: 229 | L23: 8910.31 | M23: 0.090277778 | N23: Stand-up — Session 17 | O23: 0.8 | P23: =IFERROR(ROUND(K23/O23,0),"") -> 286 | Q23: =IFERROR(ROUND((1-O23)*L23/O23,0),"") -> 2228 | R23: =ROUND(L23*M23,0) -> 804
B24: Conférence — Session 14 | C24: 294 | D24: 5828.59 | E24: 0.075581395 | F24: 0.628 | G24: 468 | H24: 3453 | K24: 450 | L24: 8741.7 | M24: 0.091269841 | N24: Danse — Session 9 | O24: 0.5875 | P24: =IFERROR(ROUND(K24/O24,0),"") -> 766 | Q24: =IFERROR(ROUND((1-O24)*L24/O24,0),"") -> 6138 | R24: =ROUND(L24*M24,0) -> 798
B25: Danse — Session 13 | C25: 535 | D25: 13238.34 | E25: 0.078947368 | F25: 0.65 | G25: 823 | H25: 7128 | K25: 533 | L25: 8378.89 | M25: 0.092948718 | N25: Concert — Session 12 | O25: 0.9325 | P25: =IFERROR(ROUND(K25/O25,0),"") -> 572 | Q25: =IFERROR(ROUND((1-O25)*L25/O25,0),"") -> 607 | R25: =ROUND(L25*M25,0) -> 779
A26: Priorité aux 5 événements à plus fort manque à gagner (impact €) ; en parallèle, traitement des 10 événements à faible remplissage (risque). | K26: 191 | L26: 6045.81 | M26: 0.125 | N26: Conférence — Session 22 | O26: 0.62666667 | P26: =IFERROR(ROUND(K26/O26,0),"") -> 305 | Q26: =IFERROR(ROUND((1-O26)*L26/O26,0),"") -> 3602 | R26: =ROUND(L26*M26,0) -> 756
P27: =IFERROR(ROUND(K27/O27,0),"") | Q27: =IFERROR(ROUND((1-O27)*L27/O27,0),"") | R27: =ROUND(L27*M27,0) -> 0
A28: Top impact | B28: event_name | C28: tickets_sold | D28: revenue | E28: no_show_rate | F28: fill_rate | G28: Capacité estimée | H28: Manque à gagner estimé | K28: 146 | L28: 5787.47 | M28: 0.12941176 | N28: Festival — Session 6 | O28: 0.76666667 | P28: =IFERROR(ROUND(K28/O28,0),"") -> 190 | Q28: =IFERROR(ROUND((1-O28)*L28/O28,0),"") -> 1761 | R28: =ROUND(L28*M28,0) -> 749
B29: Danse — Session 18 | C29: 2509 | D29: 60938.65 | E29: 0.081435473 | F29: 0.6795 | G29: 3692 | H29: 28743 | K29: 803 | L29: 10505.24 | M29: 0.069767442 | N29: Danse — Session 11 | O29: 0.82857143 | P29: =IFERROR(ROUND(K29/O29,0),"") -> 969 | Q29: =IFERROR(ROUND((1-O29)*L29/O29,0),"") -> 2173 | R29: =ROUND(L29*M29,0) -> 733
B30: Projection — Session 5 | C30: 994 | D30: 23478.3 | E30: 0.070175439 | F30: 0.51142857 | G30: 1944 | H30: 22429 | K30: 703 | L30: 8999.5 | M30: 0.076190476 | N30: Projection — Session 16 | O30: 0.42 | P30: =IFERROR(ROUND(K30/O30,0),"") -> 1674 | Q30: =IFERROR(ROUND((1-O30)*L30/O30,0),"") -> 12428 | R30: =ROUND(L30*M30,0) -> 686
B31: Conférence — Session 20 | C31: 937 | D31: 14553.74 | E31: 0.089908257 | F31: 0.43285714 | G31: 2165 | H31: 19069 | K31: 469 | L31: 7366.46 | M31: 0.076086957 | N31: Projection — Session 10 | O31: 0.6525 | P31: =IFERROR(ROUND(K31/O31,0),"") -> 719 | Q31: =IFERROR(ROUND((1-O31)*L31/O31,0),"") -> 3923 | R31: =ROUND(L31*M31,0) -> 560
B32: Projection — Session 16 | C32: 703 | D32: 8999.5 | E32: 0.076190476 | F32: 0.42 | G32: 1674 | H32: 12428 | K32: 327 | L32: 6075.22 | M32: 0.084656085 | N32: Stand-up — Session 21 | O32: 0.896 | P32: =IFERROR(ROUND(K32/O32,0),"") -> 365 | Q32: =IFERROR(ROUND((1-O32)*L32/O32,0),"") -> 705 | R32: =ROUND(L32*M32,0) -> 514
B33: Théâtre — Session 2 | C33: 1459 | D33: 27654.45 | E33: 0.088377724 | F33: 0.69833333 | G33: 2089 | H33: 11946 | K33: 294 | L33: 5828.59 | M33: 0.075581395 | N33: Conférence — Session 14 | O33: 0.628 | P33: =IFERROR(ROUND(K33/O33,0),"") -> 468 | Q33: =IFERROR(ROUND((1-O33)*L33/O33,0),"") -> 3453 | R33: =ROUND(L33*M33,0) -> 441
K34: 347 | L34: 4533.52 | M34: 0.094059406 | N34: Projection — Session 3 | O34: 0.492 | P34: =IFERROR(ROUND(K34/O34,0),"") -> 705 | Q34: =IFERROR(ROUND((1-O34)*L34/O34,0),"") -> 4681 | R34: =ROUND(L34*M34,0) -> 426
A35: Top 5 Impact no-show (€) | B35: event_name | C35: tickets_sold | D35: revenue | E35: no_show_rate | F35: fill_rate | G35: Capacité estimée | H35: Manque à gagner estimé | I35: Impact no-show (€) | K35: 459 | L35: 4781.08 | M35: 0.0859375 | N35: Concert — Session 19 | O35: 0.8325 | P35: =IFERROR(ROUND(K35/O35,0),"") -> 551 | Q35: =IFERROR(ROUND((1-O35)*L35/O35,0),"") -> 962 | R35: =ROUND(L35*M35,0) -> 411
B36: Danse — Session 18 | C36: 2509 | D36: 60938.65 | E36: 0.081435473 | F36: 0.6795 | G36: 3692 | H36: 28743 | I36: 4963 | K36: 273 | L36: 5138.11 | M36: 0.073170732 | N36: Théâtre — Session 23 | O36: 0.66 | P36: =IFERROR(ROUND(K36/O36,0),"") -> 414 | Q36: =IFERROR(ROUND((1-O36)*L36/O36,0),"") -> 2647 | R36: =ROUND(L36*M36,0) -> 376
B37: Théâtre — Session 2 | C37: 1459 | D37: 27654.45 | E37: 0.088377724 | F37: 0.69833333 | G37: 2089 | H37: 11946 | I37: 2444 | K37: 323 | L37: 4194.96 | M37: 0.089005236 | N37: Concert — Session 8 | O37: 0.9 | P37: =IFERROR(ROUND(K37/O37,0),"") -> 359 | Q37: =IFERROR(ROUND((1-O37)*L37/O37,0),"") -> 466 | R37: =ROUND(L37*M37,0) -> 373
B38: Stand-up — Session 7 | C38: 1396 | D38: 18073.07 | E38: 0.097135741 | F38: 0.7825 | G38: 1784 | H38: 5024 | I38: 1756 | K38: 182 | L38: 5596.17 | M38: 0.064814815 | N38: Théâtre — Session 4 | O38: 0.55333333 | P38: =IFERROR(ROUND(K38/O38,0),"") -> 329 | Q38: =IFERROR(ROUND((1-O38)*L38/O38,0),"") -> 4517 | R38: =ROUND(L38*M38,0) -> 363
B39: Conférence — Session 1 | C39: 568 | D39: 21645.67 | E39: 0.076687117 | F39: 0.785 | G39: 724 | H39: 5928 | I39: 1660
B40: Projection — Session 5 | C40: 994 | D40: 23478.3 | E40: 0.070175439 | F40: 0.51142857 | G40: 1944 | H40: 22429 | I40: 1648
A42: La baisse est concentrée sur quelques événements à fort manque à gagner (Danse—Session 18, Projection—Session 5, Conf—Session 20) : priorité à ces 5 pour récupérer du CA rapidement, tout en traitant en parallèle les 10 plus faibles fill_rate.
L43: Base graphique courbe CA -> Jour | M43: Jour | N43: CA
...
